<!DOCTYPE html><html lang="es"><head><meta charset="utf-8" /><title>Cómo manejar errores con try y catch en Clojure – Resuelto</title><meta content="El manejo de errores es crucial para la robustez de una aplicación. En este artículo, exploramos cómo usar try, catch y finally en Clojure." name="description" /><link href="/../../styles.css" rel="stylesheet" /><meta content="initial-scale=1, width=device-width" name="viewport" /><meta content="NEdWFaLiY4F7Mnw5exM0mj9XLjyr9mJ5VFtGVqjBeWA" name="google-site-verification" /><script type="application/ld+json">{"@context":"https://schema.org","@type":"Article","headline":"Cómo manejar errores con try y catch en Clojure – Resuelto","description":"El manejo de errores es crucial para la robustez de una aplicación. En este artículo, exploramos cómo usar try, catch y finally en Clojure.\n           Ejemplo básico\n           Capturamos una excepción para evitar que el programa falle:\n           (try\n  (/ 1 0)\n  (catch ArithmeticException e (println \"Error:\" (.getMessage e))))\n           Bloque finally\n           Usamos finally para ejecutar limpieza de recursos:\n           (try\n  (println \"Cálculo iniciado\")\n  (/ 1 0)\n  (catch Exception e (println \"Error\"))\n  (finally (println \"Fin del cálculo\")))\n           Conclusión\n           Maneja errores de manera explícita para crear sistemas más robustos y confiables."}</script><meta content="ca-pub-4545173212980791" name="google-adsense-account" /></head><script async="async" crossorigin="anonymous" src="https://pagead2.googlesyndication.com/pagead/js/adsbygoogle.js?client=ca-pub-4545173212980791"></script></html><body><div id="app"></div><main><article><h1>Cómo manejar errores con try y catch en Clojure – Resuelto</h1><p>El manejo de errores es crucial para la robustez de una aplicación. En este artículo, exploramos cómo usar <code>try</code>, <code>catch</code> y <code>finally</code> en Clojure.</p>
           <h2>Ejemplo básico</h2>
           <p>Capturamos una excepción para evitar que el programa falle:</p>
           <code>(try
  (/ 1 0)
  (catch ArithmeticException e (println "Error:" (.getMessage e))))</code>
           <h2>Bloque finally</h2>
           <p>Usamos <code>finally</code> para ejecutar limpieza de recursos:</p>
           <code>(try
  (println "Cálculo iniciado")
  (/ 1 0)
  (catch Exception e (println "Error"))
  (finally (println "Fin del cálculo")))</code>
           <h2>Conclusión</h2>
           <p>Maneja errores de manera explícita para crear sistemas más robustos y confiables.</p></article></main><footer class="footer"><div class="footer-content"><ul class="footer-links"><li><a class="footer-link" href="/politica-de-cookies">Política de Cookies</a></li><li><a class="footer-link" href="/politica-de-privacidad">Política de Privacidad</a></li><li><a class="footer-link" href="/sobre-nosotros">Sobre Nosotros</a></li></ul><div class="footer-note deaccept-cookies"><button id="unaccept-cookies">Deshacer aceptación de cookies</button></div></div><p class="footer-note">Última actualización: 14 de diciembre de 2024</p></footer><script defer="defer" src="/js/compiled/app.js"></script></body>